Workbook
Name CROF: 'Question Detail'!$H$57:$H$66
Name DER_CC: 'Question Detail'!$H$46:$H$56
Name DER_System_Services: 'Question Detail'!$H$31:$H$45
Name IBR: 'Question Detail'!$H$2:$H$16
Name Planning: 'Question Detail'!$H$80:$H$100
Name Stability: 'Question Detail'!$H$17:$H$30
Name System_Services: 'Question Detail'!$H$67:$H$79

Sheet Template
A1: Abstract_Index | B1: 1
A2: Document Title | B2: Scenario Reduction Network Based on Wasserstein Distance With Regularization
A3: Abstract | B3: Power systems with high penetration of renewable energy contain various uncertainties. Scenario-based optimization problems need a large number of discrete scenarios to obtain a reliable approximation for the probabilistic model. It is important to choose typical scenarios and ease the computational burden. This paper presents a scenario reduction network model based on Wasserstein distance. Entropy regularization is used to transform the scenario reduction problem into an unconstrained problem. Through an explicit neural network structure design, the output of the scenario reduction network corresponds to the Sinkhorn distance function. The scenario reduction network can generate the typical scenario set through unsupervised learning. An efficient algorithm is proposed for continuous/discrete scenario reduction. The superiority of the scenario reduction network model is verified through case studies. The numerical results highlight the high accuracy and computational efficiency of the proposed model over state-of-the-art models, and it makes an ideal candidate for large-scale scenario reduction problems.
A4: Main Program | B4: Other | C4: Score [0-5] | D4: Rationale | F4: Instructions: 1) Only modify colored cells. 2) Select the main program. 3) Evaluate all questions in the list. 4) Evaluate affinity score with integers 0, 1, 2, 3, 4, and 5 according to the scale below. 5) Provide a rationale for at least two low-, two medium-, and two high-classified questions. Prioritise questions where the classification was particularly difficult, uncertain, or ambiguous. Affinity Scale: Low ∎ 0: No conceptual overlap. The abstract addresses a completely different topic, phenomenon or research domain. There are no shared concepts, methods, or outcomes. Any superficial keyword match is coincidental. The abstract would not appear in a literature review for this question under any reasonable interpretation. ∎ 1: Marginal overlap. One or two terms or concepts are shared but the abstract investigates a fundamentally different question. The research domain may be adjacent but the objectives, topic, or outcomes are misaligned. Findings from this abstract could not be used to inform an answer to the question even partially. A reader would not cite this abstract as background for the question. Moderate ∎ 2: Contextual overlap. The abstract shares the general domain and studies a related concept or phenomenon, but targets a different outcome, phenomenon, or objective. The abstract provides useful background or framing but cannot directly answer the question. A reader might cite it to establish context but not as evidence. ∎ 3: Partial evidence. The abstract addresses the same research objective as the question but in a different area, context, or with a different methodological framework. Findings are relevant but require adaptation or extrapolation to apply to the question. A reader would cite this abstract as indirect or supporting evidence, not as a primary source. High ∎ 4: Direct relevance. The abstract addresses the same question, phenomenon, and outcome. Minor differences in methodology, setting, or scope exist but do not prevent the findings from being directly applicable. A reader would cite this abstract as substantive evidence for answering the question. ∎ 5: Near-perfect match. The abstract is a primary source for the question. It addresses the same research question, phenomenon, outcome, and methodology with only incidental differences. A reader would consider this abstract central to any literature review on the question.
A5: Question | B5: {=INDIRECT(B4)} -> #REF!

Sheet Batch 1
A1: Abstract_Index | B1: ='Abstracts List'!A2 -> 1
A2: Document Title | B2: ='Abstracts List'!B2 -> Scenario Reduction Network Based on Wasserstein Distance With Regularization
A3: Abstract | B3: ='Abstracts List'!C2 -> Power systems with high penetration of renewable energy contain various uncertainties. Scenario-based optimization problems need a large number of discrete scenarios to obtain a reliable approximation for the probabilistic model. It is important to choose typical scenarios and ease the computational burden. This paper presents a scenario reduction network model based on Wasserstein distance. Entropy regularization is used to transform the scenario reduction problem into an unconstrained problem. Through an explicit neural network structure design, the output of the scenario reduction network corresponds to the Sinkhorn distance function. The scenario reduction network can generate the typical scenario set through unsupervised learning. An efficient algorithm is proposed for continuous/discrete scenario reduction. The superiority of the scenario reduction network model is verified through case studies. The numerical results highlight the high accuracy and computational efficiency of the proposed model over state-of-the-art models, and it makes an ideal candidate for large-scale scenario reduction problems.
A4: Main Program | B4: Planning | C4: Score [0-5] | D4: Rationale | F4: Instructions: 1) Only modify colored cells. 2) Select the main program. 3) Evaluate all questions in the list. 4) Evaluate affinity score with integers 0, 1, 2, 3, 4, and 5 according to the scale below. 5) Provide a rationale for at least two low-, two medium-, and two high-classified questions. Prioritise questions where the classification was particularly difficult, uncertain, or ambiguous. Affinity Scale: Low ∎ 0: No conceptual overlap. The abstract addresses a completely different topic, phenomenon or research domain. There are no shared concepts, methods, or outcomes. Any superficial keyword match is coincidental. The abstract would not appear in a literature review for this question under any reasonable interpretation. ∎ 1: Marginal overlap. One or two terms or concepts are shared but the abstract investigates a fundamentally different question. The research domain may be adjacent but the objectives, topic, or outcomes are misaligned. Findings from this abstract could not be used to inform an answer to the question even partially. A reader would not cite this abstract as background for the question. Moderate ∎ 2: Contextual overlap. The abstract shares the general domain and studies a related concept or phenomenon, but targets a different outcome, phenomenon, or objective. The abstract provides useful background or framing but cannot directly answer the question. A reader might cite it to establish context but not as evidence. ∎ 3: Partial evidence. The abstract addresses the same research objective as the question but in a different area, context, or with a different methodological framework. Findings are relevant but require adaptation or extrapolation to apply to the question. A reader would cite this abstract as indirect or supporting evidence, not as a primary source. High ∎ 4: Direct relevance. The abstract addresses the same question, phenomenon, and outcome. Minor differences in methodology, setting, or scope exist but do not prevent the findings from being directly applicable. A reader would cite this abstract as substantive evidence for answering the question. ∎ 5: Near-perfect match. The abstract is a primary source for the question. It addresses the same research question, phenomenon, outcome, and methodology with only incidental differences. A reader would consider this abstract central to any literature review on the question.
A5: Question | B5: {=INDIRECT(B4)} -> 12 - What mechanisms and appropriate aggregate DER representations and data are necessary to account for DERs in system-wide operation and planning, and in techno economic evaluation?
B6: 13 - How can system operators quantify the bulk-level energy and service opportunities from DER, and how can these services be shared among distribution operators, bulk operators, aggregators and (where applicable) customers?
B7: 14 - How can bulk-level services provided by DER be valued as a compromise between simplicity and, for example, a complex full cost-reflective approach?
B8: 27 - How can risk-based methods (e.g. probabilistic forecasting techniques) be better incorporated into operational decision-support tools and used consistently across multiple stages (e.g., real-time, day ahead, intraday planning)?
B9: 32 - How should system restoration services be structured and organized in systems with few or no synchronous machines, relying on IBR technologies and variable energy resources?
B10: 33 - How should the definitions of services for IBR-dominated grids be structured and can standard services and standard characteristics be defined as reasonable for large and small IBRs and across variable renewable energy, storage, demand response interfaces and for differing procurement mechanisms?
B11: 34 - What methods could determine the need, sufficiency, and locational nature of IBR voltage control and system strength services for a given area?
B12: 35 - What models and methods, including testing, are necessary to quantify the ability of variable renewable energy to provide essential reliability services to the grid, and how do system operators quantify the value of these reliability services (for example, as an input to system-specific market/incentive design questions)?
B13: 36 - What system services can be designed to enable response from IBRs that can be a substitute for inertia (i.e. very fast frequency response)?
B14: 37 - What studies and metrics are required to identify long-term scarcity of resources (capacity, energy, flexibility etc.) to maintain reliability?
B15: 38 - How should grid enhancing technologies be included in the planning processes?
B16: 39 - What technical models need to be added to long-term planning methods and studies to consider other reliability services in addition to traditional resource adequacy and deliverability? For example, how should sufficient restoration capability be modeled in long-term reliability studies?
B17: 40 - What studies and metrics are required to evaluate resource adequacy with hybrid plants (e.g., photovoltaics-plus-storage) and virtual power plants?
... B25: 48 - What additional planning models and methods are needed to plan for a system that can withstand expected or unexpected lulls (e.g., an extended wind drought, or a dunkelflaute)?
A28: Abstract_Index | B28: ='Abstracts List'!A3 -> 103
A29: Document Title | B29: ='Abstracts List'!B3 -> Characteristic Investigation and Overvoltage Suppression of MMC-HVDC Integrated Offshore Wind Farms Under Onshore Valve-Side SPG Fault
A30: Abstract | B30: ='Abstracts List'!C3 -> The valve-side ground fault in the converter station of modular multilevel converter based high voltage direct current (MMC-HVDC) is a serious threat to the security of power systems. Hence, this paper analyzes the most common single-phase-to-ground (SPG) fault characteristics of valve-side faults in onshore converter stations of MMC-HVDC integrated offshore wind farms. The propagation and impact mechanism of onshore SPG fault to offshore HVDC transmission lines, offshore converter station, and wind farms are deduced based on the MMC control principle. Furthermore, an overvoltage suppression strategy based on zero-sequence voltage modulation is proposed. The effect mechanism of this strategy on the transient stability of the system is analyzed. The key parameter of the proposed strategy is also designed considering both the practical engineering requirements and the impact of the system operation. Finally, the theoretical analysis of fault characteristics and the proposed overvoltage suppression strategy are verified by the PSCAD/EMTDC simulation platform. Simulation results not only show good agreement with the theoretical analysis of the fault characteristics, but also prove the effectiveness of the proposed overvoltage suppression strategy.
A31: Main Program | B31: Other | C31: Score [0-5] | D31: Rationale | F31: Instructions: 1) Only modify colored cells. 2) Select the main program. 3) Evaluate all questions in the list. 4) Evaluate affinity score with integers 0, 1, 2, 3, 4, and 5 according to the scale below. 5) Provide a rationale for at least two low-, two medium-, and two high-classified questions. Prioritise questions where the classification was particularly difficult, uncertain, or ambiguous. Affinity Scale: Low ∎ 0: No conceptual overlap. The abstract addresses a completely different topic, phenomenon or research domain. There are no shared concepts, methods, or outcomes. Any superficial keyword match is coincidental. The abstract would not appear in a literature review for this question under any reasonable interpretation. ∎ 1: Marginal overlap. One or two terms or concepts are shared but the abstract investigates a fundamentally different question. The research domain may be adjacent but the objectives, topic, or outcomes are misaligned. Findings from this abstract could not be used to inform an answer to the question even partially. A reader would not cite this abstract as background for the question. Moderate ∎ 2: Contextual overlap. The abstract shares the general domain and studies a related concept or phenomenon, but targets a different outcome, phenomenon, or objective. The abstract provides useful background or framing but cannot directly answer the question. A reader might cite it to establish context but not as evidence. ∎ 3: Partial evidence. The abstract addresses the same research objective as the question but in a different area, context, or with a different methodological framework. Findings are relevant but require adaptation or extrapolation to apply to the question. A reader would cite this abstract as indirect or supporting evidence, not as a primary source. High ∎ 4: Direct relevance. The abstract addresses the same question, phenomenon, and outcome. Minor differences in methodology, setting, or scope exist but do not prevent the findings from being directly applicable. A reader would cite this abstract as substantive evidence for answering the question. ∎ 5: Near-perfect match. The abstract is a primary source for the question. It addresses the same research question, phenomenon, outcome, and methodology with only incidental differences. A reader would consider this abstract central to any literature review on the question.
A32: Question | B32: {=INDIRECT(B31)} -> #REF!
A55: Abstract_Index | B55: ='Abstracts List'!A4 -> 115
A56: Document Title | B56: ='Abstracts List'!B4 -> Adaptive Stability Contingency Screening for Operational Planning Based on Domain-Adversarial Graph Neural Network
A57: Abstract | B57: ='Abstracts List'!C4 -> Compared to contingency screening (CS) techniques that focus on thermal/voltage limit violation, CS that addresses the transient and small-signal stability contingencies in the existing references requires a higher computational cost, limiting its use to off-line contingency analysis. Therefore, it poses the challenge of developing an effective CS scheme for fast recognition of critical contingency, which is one of the major concerns of system operators. To deal with this problem, this article proposes an adaptive stability CS (SCS) scheme for operational planning. One challenge in developing the adaptive SCS for different cardinal points is data distribution discrepancy resulted from load/topology changes. To align data distribution between different domains (i.e., cardinal points), a domain-adversarial graph neural network (DAGNN) is developed to learn the domain-invariant features, so that the DAGNN model trained on the labeled source domain (e.g., peak cardinal point 2B) data can be applied to the unlabeled target domain (e.g., trough cardinal point 1B) data for SCS. To make the proposed SCS more efficient in dealing with power system data, a graph learning approach combined with graph transformer and graph isomorphism network is used in DAGNN to provide feature representations considering the graph properties of power systems, where nodes and edges refer to buses and transmission lines, respectively. Experiments on IEEE 39 Bus system and IEEE 118 Bus system have verified the effectiveness of the proposed model.
A58: Main Program | B58: Other | C58: Score [0-5] | D58: Rationale | F58: Instructions: 1) Only modify colored cells. 2) Select the main program. 3) Evaluate all questions in the list. 4) Evaluate affinity score with integers 0, 1, 2, 3, 4, and 5 according to the scale below. 5) Provide a rationale for at least two low-, two medium-, and two high-classified questions. Prioritise questions where the classification was particularly difficult, uncertain, or ambiguous. Affinity Scale: Low ∎ 0: No conceptual overlap. The abstract addresses a completely different topic, phenomenon or research domain. There are no shared concepts, methods, or outcomes. Any superficial keyword match is coincidental. The abstract would not appear in a literature review for this question under any reasonable interpretation. ∎ 1: Marginal overlap. One or two terms or concepts are shared but the abstract investigates a fundamentally different question. The research domain may be adjacent but the objectives, topic, or outcomes are misaligned. Findings from this abstract could not be used to inform an answer to the question even partially. A reader would not cite this abstract as background for the question. Moderate ∎ 2: Contextual overlap. The abstract shares the general domain and studies a related concept or phenomenon, but targets a different outcome, phenomenon, or objective. The abstract provides useful background or framing but cannot directly answer the question. A reader might cite it to establish context but not as evidence. ∎ 3: Partial evidence. The abstract addresses the same research objective as the question but in a different area, context, or with a different methodological framework. Findings are relevant but require adaptation or extrapolation to apply to the question. A reader would cite this abstract as indirect or supporting evidence, not as a primary source. High ∎ 4: Direct relevance. The abstract addresses the same question, phenomenon, and outcome. Minor differences in methodology, setting, or scope exist but do not prevent the findings from being directly applicable. A reader would cite this abstract as substantive evidence for answering the question. ∎ 5: Near-perfect match. The abstract is a primary source for the question. It addresses the same research question, phenomenon, outcome, and methodology with only incidental differences. A reader would consider this abstract central to any literature review on the question.
A59: Question | B59: {=INDIRECT(B58)} -> #REF!
A82: Abstract_Index | B82: ='Abstracts List'!A5 -> 81
A83: Document Title | B83: ='Abstracts List'!B5 -> Virtual Prosumers P2P Transaction Based Distribution Network Expansion Planning
A84: Abstract | B84: ='Abstracts List'!C5 -> The deployment of prosumers with distributed energy resources (DERs) has facilitated the prosumer-centric transactive market, giving rise to the consequent necessity for the coordination between prosumers and the distribution networks. This paper proposes an incentive-based expansion planning method considering virtual peer-to-peer (P2P) transaction among prosumers, which is characterized as a tri-level planning-operation-transaction framework. Each prosumer optimizes its internal response of DERs and external P2P transaction jointly, formulating virtual P2P transaction. Under such a paradigm, the distribution company (DISCO) identifies the optimal expansion planning in the network assets, while the independent distribution system operator (IDSO) is responsible for the optimal operation of the expanded distribution networks. To derive appropriate incentives for each prosumer, the DISCO and IDSO allocate long-term investment network charges and short-term operation network charges on prosumers, along with the designed financial transmission rights coupling multiple time scales. Through such incentives, self-profit driven virtual transactions can relieve operation problems and postpone expansion planning, acting as a short-term alternative. Moreover, a risk-based approach is proposed for prosumer to flexibly change strategy according to different risk preference. Finally, results from the case study demonstrate the superiority and effectiveness of the proposed method in the collaborative application of virtual transaction in the expansion planning.
A85: Main Program | B85: Other | C85: Score [0-5] | D85: Rationale | F85: Instructions: 1) Only modify colored cells. 2) Select the main program. 3) Evaluate all questions in the list. 4) Evaluate affinity score with integers 0, 1, 2, 3, 4, and 5 according to the scale below. 5) Provide a rationale for at least two low-, two medium-, and two high-classified questions. Prioritise questions where the classification was particularly difficult, uncertain, or ambiguous. Affinity Scale: Low ∎ 0: No conceptual overlap. The abstract addresses a completely different topic, phenomenon or research domain. There are no shared concepts, methods, or outcomes. Any superficial keyword match is coincidental. The abstract would not appear in a literature review for this question under any reasonable interpretation. ∎ 1: Marginal overlap. One or two terms or concepts are shared but the abstract investigates a fundamentally different question. The research domain may be adjacent but the objectives, topic, or outcomes are misaligned. Findings from this abstract could not be used to inform an answer to the question even partially. A reader would not cite this abstract as background for the question. Moderate ∎ 2: Contextual overlap. The abstract shares the general domain and studies a related concept or phenomenon, but targets a different outcome, phenomenon, or objective. The abstract provides useful background or framing but cannot directly answer the question. A reader might cite it to establish context but not as evidence. ∎ 3: Partial evidence. The abstract addresses the same research objective as the question but in a different area, context, or with a different methodological framework. Findings are relevant but require adaptation or extrapolation to apply to the question. A reader would cite this abstract as indirect or supporting evidence, not as a primary source. High ∎ 4: Direct relevance. The abstract addresses the same question, phenomenon, and outcome. Minor differences in methodology, setting, or scope exist but do not prevent the findings from being directly applicable. A reader would cite this abstract as substantive evidence for answering the question. ∎ 5: Near-perfect match. The abstract is a primary source for the question. It addresses the same research question, phenomenon, outcome, and methodology with only incidental differences. A reader would consider this abstract central to any literature review on the question.
A86: Question | B86: {=INDIRECT(B85)} -> #REF!
A109: Abstract_Index | B109: ='Abstracts List'!A6 -> 134
A110: Document Title | B110: ='Abstracts List'!B6 -> High-Dimensional Feature Selection for Power System Congestion Event Prognosis With Enhanced Evolutionary Computation
A111: Abstract | B111: ='Abstracts List'!C6 -> Power system congestion event prognosis (CEP) based on multivariate time series (MTS) learning is an effective way to improve the warning abilities against risky situations. However, it is still challenging to decide which measurement sequences of system variables should be selected to train MTS learning-based CEPs models, especially when facing high-dimensional candidate features from power systems. Focusing on this issue, this paper proposes a novel high-dimensional feature selection (FS) method to identify and select variables that contain beneficial data patterns for the prognosis of network congestion events. A wrapper framework embedded with multiple MTS learning models is first built to treat FS as a combinatorial optimization task and receive MTS as inputs directly without sequence compressions. Then, to improve the combinatorial optimization efficiency and FS results in the high-dimensional case, a hybrid structure called enhanced evolutionary computation (EEC) is developed by combining with information theory-based feature priority scores, which play the role of semi-guidance in the iterative search. Test results on both the real-world and synthetic datasets validate the effectiveness of the developed EEC structure and show that the selected features by the proposed FS method are more beneficial in identifying the early patterns of network congestion events, thus contributing to efficient and accurate CEP for power systems.
A112: Main Program | B112: Other | C112: Score [0-5] | D112: Rationale | F112: Instructions: 1) Only modify colored cells. 2) Select the main program. 3) Evaluate all questions in the list. 4) Evaluate affinity score with integers 0, 1, 2, 3, 4, and 5 according to the scale below. 5) Provide a rationale for at least two low-, two medium-, and two high-classified questions. Prioritise questions where the classification was particularly difficult, uncertain, or ambiguous. Affinity Scale: Low ∎ 0: No conceptual overlap. The abstract addresses a completely different topic, phenomenon or research domain. There are no shared concepts, methods, or outcomes. Any superficial keyword match is coincidental. The abstract would not appear in a literature review for this question under any reasonable interpretation. ∎ 1: Marginal overlap. One or two terms or concepts are shared but the abstract investigates a fundamentally different question. The research domain may be adjacent but the objectives, topic, or outcomes are misaligned. Findings from this abstract could not be used to inform an answer to the question even partially. A reader would not cite this abstract as background for the question. Moderate ∎ 2: Contextual overlap. The abstract shares the general domain and studies a related concept or phenomenon, but targets a different outcome, phenomenon, or objective. The abstract provides useful background or framing but cannot directly answer the question. A reader might cite it to establish context but not as evidence. ∎ 3: Partial evidence. The abstract addresses the same research objective as the question but in a different area, context, or with a different methodological framework. Findings are relevant but require adaptation or extrapolation to apply to the question. A reader would cite this abstract as indirect or supporting evidence, not as a primary source. High ∎ 4: Direct relevance. The abstract addresses the same question, phenomenon, and outcome. Minor differences in methodology, setting, or scope exist but do not prevent the findings from being directly applicable. A reader would cite this abstract as substantive evidence for answering the question. ∎ 5: Near-perfect match. The abstract is a primary source for the question. It addresses the same research question, phenomenon, outcome, and methodology with only incidental differences. A reader would consider this abstract central to any literature review on the question.
A113: Question | B113: {=INDIRECT(B112)} -> #REF!
A136: Abstract_Index | B136: ='Abstracts List'!A7 -> 71
A137: Document Title | B137: ='Abstracts List'!B7 -> Electromechanical Transient Modeling of the Low-Frequency AC System With Modular Multilevel Matrix Converter Stations
...

Sheet Question context
A1: Group | B1: Subgrouping | C1: RA2025 | D1: Questions - long | E1: 1 | F1: 103 | G1: 115 | H1: 81 | I1: 134 | J1: 71 | K1: 146 | L1: 65 | M1: 281 | N1: 241 | O1: 94 | P1: 44 | Q1: 185 | R1: 174 | S1: 194 | T1: 212 | U1: 15 | V1: 231 | W1: 228 | X1: 45 | Y1: 280
A2: IBR | B2: I1 - Power system evolution with high IBR shares | C2: 1 | D2: What is the future of active power balance as the synchronous generation fraction reduces? For example, might tightened or loosened frequency (or similar proxy for active power balance) limits lead to a more reliable, secure, lower-cost IBR-based power system?
C3: 2 | D3: How will protection systems need to change to accommodate high penetrations of IBRs, and what possible actions might an inverter take during a fault that would help fault detection and location? | F3: 3
C4: 3 | D4: How could the IBR control paradigm change from replicating synchronous machines to exploiting wider IBR flexibility without introducing integration challenges during the transition? | P4: 1
B5: I2 - IBR design standards and capabilities | C5: 4 | D5: What are the appropriate inverter capabilities and, consequently, control design methods for operation in grids with high percentages of IBRs, and are standard configurations and combinations of services helpful in simplifying operational decision-making? | F5: 2 | P5: 2 | T5: 2
C6: =C5+1 -> 5 | D6: What recommendations for standard IBR frequency characteristics and responses should be identified to help system design? For example, should a contribution to damping be mandatory at certain frequencies?
C7: =C6+1 -> 6 | D7: What requirements (e.g. impedance) should be placed on IBRs to control negative sequence currents for protection and harmonics suppression?
A8: Stability | B8: St1 - Tools for real-time operation of IBR dominated systems | C8: =C7+1 -> 7 | D8: What approaches can be taken to track the dynamic response of IBR-dominated systems near real time and detect any emerging stability problems? | F8: 1 | G8: 2 | J8: 1
B9: St2 - Methods for planning and operation of low-inertia systems | C9: =C8+1 -> 8 | D9: What methods, including data types, and analyses can be used to identify the risk of poorly damped IBR-induced oscillations in planning studies and trace their root cause?
C10: =C9+1 -> 9 | D10: What analytical tools and models should be provided to planners and operators for robust assessment of system performance in IBR-dominated power grids? | F10: 2 | G10: 2 | J10: 3 | T10: 2
C11: =C10+1 -> 10 | D11: What methods and tools should be used in planning and/or operation to determine the appropriate mix, location, and capabilities of grid-forming and grid-following inverters to mitigate stability problems for a given power system? | T11: 3
C12: =C11+1 -> 11 | D12: In what form and fidelity should the original equipment manufacturers/developers and system operators exchange the IBR and grid models for comprehensive stability assurance of IBR-dominated grids? | J12: 1
A13: DER System Services | B13: D3 - Bulk system services | C13: =C12+1 -> 12 | D13: What mechanisms and appropriate aggregate DER representations and data are necessary to account for DERs in system-wide operation and planning, and in techno economic evaluation? | H13: 3 | L13: 1 | O13: 1 | V13: 3 | X13: 1
C14: =C13+1 -> 13 | D14: How can system operators quantify the bulk-level energy and service opportunities from DER, and how can these services be shared among distribution operators, bulk operators, aggregators and (where applicable) customers? | H14: 1 | L14: 1 | O14: 1 | V14: 3 | W14: 1 | X14: 1
C15: =C14+1 -> 14 | D15: How can bulk-level services provided by DER be valued as a compromise between simplicity and, for example, a complex full cost-reflective approach? | H15: 2 | L15: 1 | V15: 1 | W15: 1 | X15: 1
A16: DER C&C | B16: D1 - DER Aggregation, measurement & control | C16: =C15+1 -> 15 | D16: What aggregate quantities must be monitored, screened, and validated to ensure reliable service provision from different DER categories and at what temporal and/or spatial resolution must these processes occur? | L16: 2 | O16: 2 | W16: 1 | X16: 2
C17: =C16+1 -> 16 | D17: What is the communication capability needed to support monitoring and coordination of DER in terms of reliability, latency, bandwidth and (cyber) security? | L17: 3
B18: D2 - Data and control architecture | C18: =C17+1 -> 17 | D18: What is a scalable data architecture for DER monitoring, modelling, and coordination in real-time that would be suitable for the control room? | L18: 2
C19: =C18+1 -> 18 | D19: What are the relative merits of different coordination architectures for DER with respect to appropriateness for device characterizations, accounting for practical constraints around communication and computation, different types of aggregators, different DER objectives and heterogeneity and existing distribution system operator/system operator schemes? | L19: 2 | W19: 1
A20: CROF | B20: C1 - Flexibility assessment | C20: =C19+1 -> 19 | D20: How can the capabilities of grid-enhancing technologies (such as FACTS,SPS, RAS, DLR, PFC, WAMPAC) be integrated into the operational decision-making process? | F20: 1
C21: =C20+1 -> 20 | D21: How can grid topology be flexibly adapted to be reliably integrated into the operational decision-making process with outage scheduling, transfer limit increase, and post contingency remedial actions? | G21: 3 | I21: 2 | K21: 2
C22: =C21+1 -> 21 | D22: What applications are required to assess adequate flexibility from all resources, including those on the transmission, distribution and coupled energy systems (e.g., heat, electric vehicles, etc.) in the near term, and how can these resources be applied to address uncertainty during real-time applications? | I22: 2 | M22: 1 | O22: 2 | U22: 2 | V22: 3 | X22: 2
B23: C2 - Data and digital architecture | C23: =C22+1 -> 22 | D23: What type of digital architecture is best placed to enable modularity and the variety of software required to operate a control room in real time, near-real time, and in auto pilot mode?
C24: =C23+1 -> 23 | D24: What is the best way to integrate large datasets, streaming information, and historical system performance to create actionable operational insights in an increasingly complex environment with multiple phenomena occurring within overlapping timescales? | E24: 1 | I24: 2
B25: C3 - Security assessment | C25: =C24+1 -> 24 | D25: How can the risk of high-impact low-probability events (weather-related and otherwise) be incorporated into security assessments in real time and operations planning? | E25: 2 | G25: 1 | I25: 1
C26: =C25+1 -> 25 | D26: What metrics and their definitions (system strength, inertia, or others) need to be appropriately monitored or calculated to assess system dynamic behavior in real time, and what monitoring capabilities are necessary to support these assessments? | F26: 1
B27: C4 - Visualization | C27: =C26+1 -> 26 | D27: What improvements can be made to predictive tools and visualization methodologies in operational applications within the control room to support decision-making in real-time operations? | I27: 2 | K27: 4 | U27: 1
B28: C5 - Forecasting | C28: =C27+1 -> 27 | D28: How can risk-based methods (e.g. probabilistic forecasting techniques) be better incorporated into operational decision-support tools and used consistently across multiple stages (e.g., real-time, day ahead, intraday planning)? | E28: 2 | I28: 2 | N28: 1
A29: System Services | B29: SS1 - System needs | C29: =C28+1 -> 28 | D29: What system services are needed across different timescales and to the extent that services coexist within the same timescale, how should these services be designed to avoid competition and overlap? | X29: 1
C30: =C29+1 -> 29 | D30: What are the needs of a power system expressed in technologically neutral form and how do these needs map to services that any resource (including data centers, other IBRs, DERs, high-voltage direct current links, etc.) can provide? | L30: 2 | M30: 2 | O30: 2 | X30: 1
C31: =C30+1 -> 30 | D31: How can system performance requirements be translated into reliable new technology solutions? | M31: 2 | P31: 3
C32: =C31+1 -> 31 | D32: For each service, how feasible is it to provide from IBR, what “cost” does it add, what limitations exist on its magnitude and duration and what are the trade-offs between the provision of services?
B33: SS2 - Services design | C33: =C32+1 -> 32 | D33: How should system restoration services be structured and organized in systems with few or no synchronous machines, relying on IBR technologies and variable energy resources?
C34: =C33+1 -> 33 | D34: How should the definitions of services for IBR-dominated grids be structured and can standard services and standard characteristics be defined as reasonable for large and small IBRs and across variable renewable energy, storage, demand response interfaces and for differing procurement mechanisms? | L34: 2 | M34: 2 | P34: 1 | V34: 2
C35: =C34+1 -> 34 | D35: What methods could determine the need, sufficiency, and locational nature of IBR voltage control and system strength services for a given area? | F35: 1 | M35: 1
C36: =C35+1 -> 35 | D36: What models and methods, including testing, are necessary to quantify the ability of variable renewable energy to provide essential reliability services to the grid, and how do system operators quantify the value of these reliability services (for example, as an input to system-specific market/incentive design questions)? | E36: 1 | F36: 1 | L36: 2 | M36: 2 | O36: 1 | P36: 2 | S36: 1 | U36: 1 | V36: 2 | X36: 1
C37: =C36+1 -> 36 | D37: What system services can be designed to enable response from IBRs that can be a substitute for inertia (i.e. very fast frequency response)? | M37: 3 | P37: 3
A38: Planning | B38: P2 - Resource Adequacy | C38: =C37+1 -> 37 | D38: What studies and metrics are required to identify long-term scarcity of resources (capacity, energy, flexibility etc.) to maintain reliability? | E38: 2
C39: =C38+1 -> 38 | D39: How should grid enhancing technologies be included in the planning processes? | J39: 1
C40: =C39+1 -> 39 | D40: What technical models need to be added to long-term planning methods and studies to consider other reliability services in addition to traditional resource adequacy and deliverability? For example, how should sufficient restoration capability be modeled in long-term reliability studies? | E40: 1 | H40: 1 | J40: 1 | V40: 2 | X40: 2
...

Sheet Rationale
A1: Abstract_Index | B1: Document Title | C1: Abstract | D1: RA2025_ID | E1: RA_Question | F1: Evaluator_Affinity_Level | G1: Evaluator_Score | H1: adjudicated_level | I1: Final_Reason | J1: Why this score was assigned to the abstract? | K1: Why does this abstract fall below the next relevance level?
A2: 65 | B2: Cooperative Hierarchical Control of Isolated Microgrids Considering Energy Storage System Aggregation | C2: =_xlfn.XLOOKUP(A2,'Abstracts List'!A:A,'Abstracts List'!C:C) -> The integration of numerous energy storage systems (ESSs) improves the reliable and economic operation of microgrids but also enlarges the burden of control and communication systems. This article proposes a cooperative hierarchical control for isolated microgrids with ESSs, which fully frees from the centralized paradigm and is therefore superior in flexibility and scalability. Firstly, the ESS cooperative control based on the distributed frequency controller is introduced for the state of charge (SoC) balance and the frequency regulation. Then, the ESS aggregation is considered. The aggregated ESS model is established and the real-time model parameters are derived by proposed distributed state observers. Finally, energy management is employed to allocate the output power between generators and the aggregated ESS. A detailed theoretical analysis of the dynamic and steady-state performance of proposed controllers and observers is provided. Simulations on the IEEE 33-bus and the 69-bus system verify the effectiveness of proposed methods. | D2: 12 | E2: What mechanisms and appropriate aggregate DER representations and data are necessary to account for DERs in system-wide operation and planning, and in techno economic evaluation? | F2: Low | G2: {=_xlfn.XLOOKUP(D2, 'Question context'!$C$2:$C$49, _xlfn.XLOOKUP(A2, 'Question context'!$E$1:$Y$1, 'Question context'!$E$2:$Y$49))} -> 1 | H2: Moderate | I2: Most models rated this strongly (60â€“86). I resolved high because the paper directly develops an aggregated ESS representation and derives real-time model parameters via distributed observers, which is closely aligned with aggregate DER representations for operation. The score is slightly reduced because planning and techno-economic evaluation are not central themes. | J2: There are some potential links between the content of this research paper and the G-PST research question. In particular Microgrids can be considered to be DERs to some extent and by controlling them you are potentially making them somewhat like an aggregated DER resource. Some of the concepts like observability mentioned in the abstract of the paper are also potentially of interest. | K2: There is nothing direct within the abstract of the paper to link directly to aggregation and DERs. The links are at best second hand. The overall application of the paper is on a test system not a real system and there is mention of the word theoretical which is not a confidence building term with respect to a real application.
A3: 94 | B3: An AC-Feasible Linear Model in Distribution Networks With Energy Storage | C3: =_xlfn.XLOOKUP(A3,'Abstracts List'!A:A,'Abstracts List'!C:C) -> With the increasing deployment of distributed energy resources (DERs), dispatching DERs subject to operational constraints in distribution networks draws much attention. One challenge is the non-convexities in 1) system-wide AC power flow constraints and 2) the individual complementarity constraint of energy storage. To resolve this challenge, this paper studies an AC-feasible linear model in distribution networks with energy storage, including its formulation, analysis, and applications. First, an AC-feasible linear model is formulated as a set of linear constraints on controllable DERs and uncontrollable power demand by 1) converting the non-convex system-wide constraints into linear constraints based on the Brouwer's fixed-point theorem and the second-order Taylor expansion, and 2) replacing the non-convex individual complementarity constraint of energy storage with one properly designed linear constraint. Furthermore, to analyze the power demand level at which the proposed linear model can provide a solution, this paper proposes an examination-based projection method under the Monte Carlo framework to handle projections of thousands of dimensions from linear constraints over time periods. Finally, the potential applications of our AC-feasible linear model are discussed. Numerical experiments are conducted in the IEEE 33-bus and 136-bus test systems to demonstrate the effectiveness of the proposed methods. | D3: 13 | E3: How can system operators quantify the bulk-level energy and service opportunities from DER, and how can these services be shared among distribution operators, bulk operators, aggregators and (where applicable) customers? | F3: Low | G3: {=_xlfn.XLOOKUP(D3, 'Question context'!$C$2:$C$49, _xlfn.XLOOKUP(A3, 'Question context'!$E$1:$Y$1, 'Question context'!$E$2:$Y$49))} -> 1 | H3: Moderate | I3: Most models rated this moderate-to-high because the paper develops an AC-feasible dispatch model for DERs and storage, which helps quantify feasible DER capabilities at a system level. I discounted the highest scores because the abstract does not address bulk-level service valuation or how benefits are shared among bulk operators, DSOs, aggregators, and customers. | J3: There are some potential links between the content of this research paper and the G-PST research question. In particular this is about DERs and accounting for the constraints that DERs have - this is linked with the primary objective of the G-PST research question which is quantification of services and constrainst in the distribution system are a key to understand that. There is also potential applications is mentioned in the abstract of the papaer which is at least accepting application may be important. | K3: The focus of the paper is on the distribution network and not the transmissio network - in order for it t be scored higher it would need to focus on the transmission system. The paper abstract is very focussed on the details of the formulation of an optimisation prolem and some theory and not on the formulation of an real applied problem. Test results are from a test system and not a real sysytem with no obvius link to real industry stakeholders and/or real applications focussed work.
A4: 194 | B4: Analysis of Long-Term Indicators in the British Balancing Market | C4: =_xlfn.XLOOKUP(A4,'Abstracts List'!A:A,'Abstracts List'!C:C) -> Proactive participation of uncertain renewable generation in the day-ahead (DA) wholesale market effectively reduces the system marginal price and carbon emissions, whilst significantly increasing the volumes of real-time balancing mechanism prices to ensure system security and stability. To solve the conflicting interests over the two timescales, this article: 1) proposes a novel hierarchical optimization model to align with the actual operation paradigms of the hierarchical market, whereby the capacity allocation matrix is adopted to coordinate the DA and balancing markets; 2) mathematically formulates and quantitatively analyses the long-term driving factors of balancing actions, enabling system operators (SOs) to design efficient and well-functioning market structures to meet economic and environmental targets; 3) empowers renewable generating units and flexible loads to participate in the balancing market (BM) as Ã¢â‚¬ËœactiveÃ¢â‚¬â„¢ actors and enforces the non-discriminatory provision of balancing services. The performance of the proposed model is validated on a modified IEEE 39-bus power system and a reduced GB network. Results reveal that with effective resource allocation in different timescales of the hierarchical market, the drop speed of balancing costs soars while the intermittent generation climbs. The proposed methodology enables SOs to make the most of all resources available in the market and balance the system flexibly and economically. It thus safeguards the climate mitigation pathways against the risks of substantially higher balancing costs. | D4: 35 | E4: What models and methods, including testing, are necessary to quantify the ability of variable renewable energy to provide essential reliability services to the grid, and how do system operators quantify the value of these reliability services (for example, as an input to system-specific market/incentive design questions)?Â | F4: Low | G4: {=_xlfn.XLOOKUP(D4, 'Question context'!$C$2:$C$49, _xlfn.XLOOKUP(A4, 'Question context'!$E$1:$Y$1, 'Question context'!$E$2:$Y$49))} -> 1 | H4: High | J4: There are potential links between the paper abstract and the G-PST research question. In particular the paper is addressing the british balancing market and the research question is asking can variable renewable energy provide services. The link if it is there is on the methods side. | K4: The potential links identified between the paper abstract and the G-PST research question are possibling misleading so scoring any higher is simply not justified. may not actually have anything of value
A5: 44 | B5: Hierarchical Control Strategy for Effective Virtual Frequency Responses of Multiple WPPs | C5: =_xlfn.XLOOKUP(A5,'Abstracts List'!A:A,'Abstracts List'!C:C) -> When renewable energy-based generations are increasing, they are subject to cause frequency stability problems in a power system. To solve this problem, various virtual inertial control methods (VICMs) have been recently developed. However, they all have dealt not with the steady-state frequency stability, but only with dynamic frequency stability issues. In particular, the wind power plants (WPPs) operated by these VICMs can only provide a similar inertial response (IR) to that by conventional synchronous generators without providing the primary frequency response (PFR). This results in lowering the settling frequency (SF) below the maximum steady-state frequency deviation (MSSD) band. This paper proposes the new hierarchical control strategy for the WPPs, which are operated by three virtual frequency response control methods (VFRCMs) to provide both IR and PFR. Firstly, the VFRCM-1 provides virtual IR. Next, the VFRCM-2 increases the output power from the WPPs to prevent the frequency drop, which can occur after the frequency nadir is arrested. Finally, the VFRCM-3 makes the WPPs possible to raise the SF above the MSSD band by providing the virtual PFR. The effectiveness of proposed hierarchical control strategy is verified by several case studies on the IEEE 39-bus test system with the high penetration of renewables. | D5: 3 | E5: How could the IBR control paradigm change from replicating synchronous machines to exploiting wider IBR flexibility without introducing integration challenges during the transition? | F5: Low | G5: {=_xlfn.XLOOKUP(D5, 'Question context'!$C$2:$C$49, _xlfn.XLOOKUP(A5, 'Question context'!$E$1:$Y$1, 'Question context'!$E$2:$Y$49))} -> 1 | H5: High | I5: Model scores were consistently high (70â€“84). The abstract clearly moves beyond simple synchronous-machine-like inertia emulation by adding layered virtual inertial and primary frequency response from wind plants. I kept the score below the maximum because it does not really address transition/integration challenges, only the control paradigm shift itself. | J5: There is a potential link between the paper astract which is focussed on controlling wind power plants to provide so called virtual frequency response and the G-PST research question which is focussed on the IBR control paradigm. The assumption is that IBR control and WPP control share a lot in common. | K5: The link identified may not result in any synergy between the research being reported in the paper and the G-PST research question. While IBRs and WPPs do share some things in common the link in this instance may not actually amount to anything of interest. There is also no mention of any real application or involvement of system operators and industry and the results are on a test system not a real system.
A6: 81 | B6: Virtual ProsumersÃƒÂ¢Ã¢â€šÂ¬Ã¢â€žÂ¢ P2P Transaction Based Distribution Network Expansion Planning | C6: =_xlfn.XLOOKUP(A6,'Abstracts List'!A:A,'Abstracts List'!C:C) -> The deployment of prosumers with distributed energy resources (DERs) has facilitated the prosumer-centric transactive market, giving rise to the consequent necessity for the coordination between prosumers and the distribution networks. This paper proposes an incentive-based expansion planning method considering virtual peer-to-peer (P2P) transaction among prosumers, which is characterized as a tri-level planning-operation-transaction framework. Each prosumer optimizes its internal response of DERs and external P2P transaction jointly, formulating virtual P2P transaction. Under such a paradigm, the distribution company (DISCO) identifies the optimal expansion planning in the network assets, while the independent distribution system operator (IDSO) is responsible for the optimal operation of the expanded distribution networks. To derive appropriate incentives for each prosumer, the DISCO and IDSO allocate long-term investment network charges and short-term operation network charges on prosumers, along with the designed financial transmission rights coupling multiple time scales. Through such incentives, self-profit driven virtual transactions can relieve operation problems and postpone expansion planning, acting as a short-term alternative. Moreover, a risk-based approach is proposed for prosumer to flexibly change strategy according to different risk preference. Finally, results from the case study demonstrate the superiority and effectiveness of the proposed method in the collaborative application of virtual transaction in the expansion planning. | D6: 13 | E6: How can system operators quantify the bulk-level energy and service opportunities from DER, and how can these services be shared among distribution operators, bulk operators, aggregators and (where applicable) customers? | F6: Low | G6: {=_xlfn.XLOOKUP(D6, 'Question context'!$C$2:$C$49, _xlfn.XLOOKUP(A6, 'Question context'!$E$1:$Y$1, 'Question context'!$E$2:$Y$49))} -> 1 | H6: High | I6: Most models rated this moderately to strongly relevant because the paper quantifies DER/prosumer transactions, allocates network charges, and coordinates value sharing among prosumers, DISCO, and IDSO. I discounted the highest score because the work is distribution-centric and does not truly quantify bulk-level opportunities or sharing with bulk operators in a full transmission sense. | J6: DERs and one of the stakeholders the prosumer are identified in the abstact of the papaer which has potential links to quantification of services frm DERs and sharing of these amoung other stakeholders. | K6: The identified G-PST research question is in the services area yet the paper is tackling a plannig problem so the links identified are at best tangential and at worst non existent. The whole area of transactive energy and markets is out of scope for G-PST research question so that is a poor indicator of strong links. The application domain and/or time frame of the paper and the G-PST research question may differ it loks like the paper is targeting planning while the G-PST research question i sin the operations time frame.
A7: 241 | B7: Adaptive Weighted Combination Approach for Wind Power Forecast Based on Deep Deterministic Policy Gradient Method | C7: =_xlfn.XLOOKUP(A7,'Abstracts List'!A:A,'Abstracts List'!C:C) -> Accurate wind power forecast (WPF) is critical for ensuring secure and economic operation of a power system, and combination forecasting approaches for WPF have been proved effective on attaining accurate forecasting results. However, the weights in a combination forecasting model are usually predetermined based on the global performance on the training set, limiting the adaptability of the model to different scenarios. To further enhance the accuracy and effectiveness of the combination forecasting approaches, this article proposes an adaptive weighted combination forecasting approach based on the deep deterministic policy gradient (DDPG) so as to consider the local behavior accompanied by the change of external environment. Three sub-models are first selected considering the equal-likelihood and dispersion indices to construct a combination model. Then, the DDPG agent is trained to act as a weight generator by interacting with the environment and to maximize the reward. Thus, the DDPG agent can perceive the environmental changes online and dynamically weight the sub-models to attain accurate forecasting results. Case studies demonstrate that the forecasting accuracy of the proposed approach is better than that of all sub-models and several benchmark combination forecasting approaches. | D7: 27 | E7: How can risk-based methods (e.g. probabilistic forecasting techniques) be better incorporated into operational decision-support tools and used consistently across multiple stages (e.g., real-time, day ahead, intraday planning)? | F7: Low | G7: {=_xlfn.XLOOKUP(D7, 'Question context'!$C$2:$C$49, _xlfn.XLOOKUP(A7, 'Question context'!$E$1:$Y$1, 'Question context'!$E$2:$Y$49))} -> 1 | H7: High | I7: This is one of the strongest matches. The paper directly proposes an adaptive forecasting method using DDPG for online weighting under changing conditions, which aligns well with incorporating advanced predictive/risk-aware methods into operational decision support. I tempered the very high scores slightly because the abstract does not explicitly address consistency across multiple operational stages such as day-ahead, intraday, and real-time. | J7: This is an incremental piece of research that does not directly address and of the G-PST research questions but does paotentially have some links to some aspects of the research agenda. | K7: There are no real practical applications. It is mainly methological and incremental and it is at best a small potential contribution to a very secondary aspect of the much more impactful research question.
A8: 94 | B8: An AC-Feasible Linear Model in Distribution Networks With Energy Storage | C8: =_xlfn.XLOOKUP(A8,'Abstracts List'!A:A,'Abstracts List'!C:C) -> With the increasing deployment of distributed energy resources (DERs), dispatching DERs subject to operational constraints in distribution networks draws much attention. One challenge is the non-convexities in 1) system-wide AC power flow constraints and 2) the individual complementarity constraint of energy storage. To resolve this challenge, this paper studies an AC-feasible linear model in distribution networks with energy storage, including its formulation, analysis, and applications. First, an AC-feasible linear model is formulated as a set of linear constraints on controllable DERs and uncontrollable power demand by 1) converting the non-convex system-wide constraints into linear constraints based on the Brouwer's fixed-point theorem and the second-order Taylor expansion, and 2) replacing the non-convex individual complementarity constraint of energy storage with one properly designed linear constraint. Furthermore, to analyze the power demand level at which the proposed linear model can provide a solution, this paper proposes an examination-based projection method under the Monte Carlo framework to handle projections of thousands of dimensions from linear constraints over time periods. Finally, the potential applications of our AC-feasible linear model are discussed. Numerical experiments are conducted in the IEEE 33-bus and 136-bus test systems to demonstrate the effectiveness of the proposed methods. | D8: 12 | E8: What mechanisms and appropriate aggregate DER representations and data are necessary to account for DERs in system-wide operation and planning, and in techno economic evaluation? | F8: Low | G8: {=_xlfn.XLOOKUP(D8, 'Question context'!$C$2:$C$49, _xlfn.XLOOKUP(A8, 'Question context'!$E$1:$Y$1, 'Question context'!$E$2:$Y$49))} -> 1 | H8: High | I8: There is strong cross-model agreement that this is one of the best matches. The paper proposes aggregate linear representations of controllable DERs and storage with AC-feasible network constraints for operation/planning. I stopped short of an even higher score because mechanisms, data requirements, and techno-economic evaluation are not deeply developed. | J8: There may be some potential link between the research as described in the abstract and the G-PST research question. This link is embodied in the focus on DErs in both the paper and the research question but the link is at best tenous. | K8: An incremental piece of research is reported in the abstract of the paper and it is not directly related to the G-PST research question. It is also fixated on methodology and only conducts some numerical experiments with no sign of a real application.
